[{"client_msg_id":"0cd96372-8836-4d5d-ad7f-06ab5a5e78af","type":"message","user":"U6XP9LZ6V","text":"いずれにせよ、8.2.1830 以降で問題は起きてなさそうなのでよかった","ts":"1602727449.315400","team":"T03C4RC8V","replace_original":false,"delete_original":false,"blocks":[{"type":"rich_text","block_id":"WjipR"}]},{"client_msg_id":"31faf2c5-1ee1-4b90-94e8-596e670fa3db","type":"message","user":"UAZ33BKV2","text":"おっと :mattn_yoshi:","ts":"1602727173.314700","team":"T03C4RC8V","replace_original":false,"delete_original":false,"blocks":[{"type":"rich_text","block_id":"YuPQJ"}]},{"client_msg_id":"ecd3221a-7111-41b9-b720-1955a21b4181","type":"message","user":"U6XP9LZ6V","text":"python3 の件、8.2.184 で問題なく動いているという報告が来て、そんな古いので何言ってんのと思ったら 8.2.1840 だったｗ","ts":"1602727118.314300","team":"T03C4RC8V","replace_original":false,"delete_original":false,"blocks":[{"type":"rich_text","block_id":"5jU+C"}]}]
