[{"client_msg_id":"6ab1d284-b658-4db0-aa40-dcfba40c2bfc","type":"message","user":"U7H4TJEG0","text":"`:echo sort(range(10), 'get')` で同じエラーが何度も出るのは仕様なんですかね (call_funcがOKを返すので仕方なさそうだが)","ts":"1579234119.000900","team":"T03C4RC8V","replace_original":false,"delete_original":false,"blocks":[{"type":"rich_text","block_id":"OqgU"}],"source_team":"T03C4RC8V","user_team":"T03C4RC8V"}]
